<?xml version="1.0" encoding="utf-8"?>
<!-- This URDF was automatically created by SolidWorks to URDF Exporter! Originally created by Stephen Brawner (brawner@gmail.com) 
     Commit Version: 1.6.0-4-g7f85cfe  Build Version: 1.6.7995.38578
     For more information, please see http://wiki.ros.org/sw_urdf_exporter -->
<robot
  name="manipulator">
  <link
    name="base_link">
    <inertial>
      <origin
        xyz="0 -3.46944695195361E-18 0.020756318329721"
        rpy="0 0 0" />
      <mass
        value="0.0136482597260318" />
      <inertia
        ixx="1.65577962638559E-06"
        ixy="3.6292006538487E-22"
        ixz="-1.18733793538444E-22"
        iyy="1.65577962638559E-06"
        iyz="3.62112589680658E-23"
        izz="1.42772694913283E-06" />
    </inertial>
    <visual>
      <origin
        xyz="0 0 0"
        rpy="0 0 0" />
      <geometry>
        <mesh
          filename="package://manipulator/meshes/base_link.STL" />
      </geometry>
      <material
        name="">
        <color
          rgba="1 1 1 1" />
      </material>
    </visual>
    <collision>
      <origin
        xyz="0 0 0"
        rpy="0 0 0" />
      <geometry>
        <mesh
          filename="package://manipulator/meshes/base_link.STL" />
      </geometry>
    </collision>
  </link>
  <link
    name="1_Link">
    <inertial>
      <origin
        xyz="-0.000267365137948325 0.0322213217045028 0.052363401771148"
        rpy="0 0 0" />
      <mass
        value="0.572142027172773" />
      <inertia
        ixx="0.000559506390730263"
        ixy="3.18632749798054E-07"
        ixz="2.99922016851784E-06"
        iyy="0.000713508475732934"
        iyz="-1.13207704262002E-06"
        izz="0.000632369183236846" />
    </inertial>
    <visual>
      <origin
        xyz="0 0 0"
        rpy="0 0 0" />
      <geometry>
        <mesh
          filename="package://manipulator/meshes/1_Link.STL" />
      </geometry>
      <material
        name="">
        <color
          rgba="1 1 1 1" />
      </material>
    </visual>
    <collision>
      <origin
        xyz="0 0 0"
        rpy="0 0 0" />
      <geometry>
        <mesh
          filename="package://manipulator/meshes/1_Link.STL" />
      </geometry>
    </collision>
  </link>
  <joint
    name="1-joint"
    type="revolute">
    <origin
      xyz="0 0 0.0025"
      rpy="0 0 0" />
    <parent
      link="base_link" />
    <child
      link="1_Link" />
    <axis
      xyz="0 0 1" />
    <limit
    lower="-3.1365"
    upper="3.1328"
    effort="27"
    velocity="1.5" />
  </joint>
  <link
    name="2_Link">
    <inertial>
      <origin
        xyz="-0.0867008161599005 0.0248315280391652 0.000307776779842561"
        rpy="0 0 0" />
      <mass
        value="0.645668930110417" />
      <inertia
        ixx="0.000307542056564557"
        ixy="-5.26312203306795E-07"
        ixz="-4.26877816035754E-07"
        iyy="0.00169171936404808"
        iyz="-1.44486699177229E-07"
        izz="0.00158648718648665" />
    </inertial>
    <visual>
      <origin
        xyz="0 0 0"
        rpy="0 0 0" />
      <geometry>
        <mesh
          filename="package://manipulator/meshes/2_Link.STL" />
      </geometry>
      <material
        name="">
        <color
          rgba="0.850980392156863 0.850980392156863 0.850980392156863 1" />
      </material>
    </visual>
    <collision>
      <origin
        xyz="0 0 0"
        rpy="0 0 0" />
      <geometry>
        <mesh
          filename="package://manipulator/meshes/2_Link.STL" />
      </geometry>
    </collision>
  </link>
  <joint
    name="2-joint"
    type="revolute">
    <origin
      xyz="0 -0.02455 0.0665000000000001"
      rpy="0 0 0" />
    <parent
      link="1_Link" />
    <child
      link="2_Link" />
    <axis
      xyz="0 1 0" />
    <limit
      lower="0"
      upper="2.6834"
      effort="40"
      velocity="1.5" />
  </joint>
  <link
    name="3_Link">
    <inertial>
      <origin
        xyz="0.0518193953956891 0.0307794526729386 -0.000573435076948126"
        rpy="0 0 0" />
      <mass
        value="0.56534838958726" />
      <inertia
        ixx="0.000359363572006992"
        ixy="-2.39573323741015E-06"
        ixz="1.40052921349166E-05"
        iyy="0.000691885924365659"
        iyz="7.93999090679245E-07"
        izz="0.000798121896584267" />
    </inertial>
    <visual>
      <origin
        xyz="0 0 0"
        rpy="0 0 0" />
      <geometry>
        <mesh
          filename="package://manipulator/meshes/3_Link.STL" />
      </geometry>
      <material
        name="">
        <color
          rgba="1 1 1 1" />
      </material>
    </visual>
    <collision>
      <origin
        xyz="0 0 0"
        rpy="0 0 0" />
      <geometry>
        <mesh
          filename="package://manipulator/meshes/3_Link.STL" />
      </geometry>
    </collision>
  </link>
  <joint
    name="3-joint"
    type="revolute">
    <origin
      xyz="-0.226380000000001 -0.0835500000000032 0"
      rpy="0 0 0" />
    <parent
      link="2_Link" />
    <child
      link="3_Link" />
    <axis
      xyz="0 -1 0" />
    <limit
      lower="0"
      upper="1.677"
      effort="27"
      velocity="1.5" />
  </joint>
  <link
    name="4_Link">
    <inertial>
      <origin
        xyz="0.0232312139104758 0.00491771202401214 0.00289567123824075"
        rpy="0 0 0" />
      <mass
        value="0.153929257708957" />
      <inertia
        ixx="7.96382155520153E-05"
        ixy="-1.40226091859026E-06"
        ixz="-1.34662751942027E-06"
        iyy="7.53208838302305E-05"
        iyz="7.08779596545809E-07"
        izz="9.63802780992277E-05" />
    </inertial>
    <visual>
      <origin
        xyz="0 0 0"
        rpy="0 0 0" />
      <geometry>
        <mesh
          filename="package://manipulator/meshes/4_Link.STL" />
      </geometry>
      <material
        name="">
        <color
          rgba="0.850980392156863 0.850980392156863 0.850980392156863 1" />
      </material>
    </visual>
    <collision>
      <origin
        xyz="0 0 0"
        rpy="0 0 0" />
      <geometry>
        <mesh
          filename="package://manipulator/meshes/4_Link.STL" />
      </geometry>
    </collision>
  </link>
  <joint
    name="4-joint"
    type="revolute">
    <origin
      xyz="0.167395812911923 0.0315000000000018 -0.00118398460991795"
      rpy="0 0 0" />
    <parent
      link="3_Link" />
    <child
      link="4_Link" />
    <axis
      xyz="-0.999974987526421 0 0.00707278739496964" />
    <limit
      lower="-1.79677778"
      upper="1.79677778"
      effort="27"
      velocity="1.5" />
  </joint>
  <link
    name="5_Link">
    <inertial>
      <origin
        xyz="0.0521273881552066 0.039941759032185 -0.0197847588038614"
        rpy="0 0 0" />
      <mass
        value="0.254987959093994" />
      <inertia
        ixx="0.00019672731079621"
        ixy="-3.19285554548973E-07"
        ixz="3.77662689788796E-05"
        iyy="0.00018192422437189"
        iyz="1.03823397751912E-06"
        izz="0.000285168642114714" />
    </inertial>
    <visual>
      <origin
        xyz="0 0 0"
        rpy="0 0 0" />
      <geometry>
        <mesh
          filename="package://manipulator/meshes/5_Link.STL" />
      </geometry>
      <material
        name="">
        <color
          rgba="0.850980392156863 0.850980392156863 0.850980392156863 1" />
      </material>
    </visual>
    <collision>
      <origin
        xyz="0 0 0"
        rpy="0 0 0" />
      <geometry>
        <mesh
          filename="package://manipulator/meshes/5_Link.STL" />
      </geometry>
    </collision>
  </link>
  <joint
    name="5-joint"
    type="revolute">
    <origin
      xyz="0.0359990995509461 -0.0300000000000021 -0.000254620346217899"
      rpy="0 0 0" />
    <parent
      link="4_Link" />
    <child
      link="5_Link" />
    <axis
      xyz="0 -1 0" />
    <limit
      lower="-1.677"
      upper="0"
      effort="7"
      velocity="1.5" />
  </joint>
  <link
    name="6Link">
    <inertial>
      <origin
        xyz="0.0172084069593025 -0.00502315236768684 0.00969973997445769"
        rpy="0 0 0" />
      <mass
        value="0.0433474772069015" />
      <inertia
        ixx="2.22639895119428E-05"
        ixy="-9.06568613473403E-07"
        ixz="-3.30357711272234E-06"
        iyy="9.46379686009132E-06"
        iyz="-2.09246225467455E-06"
        izz="1.60702517233558E-05" />
    </inertial>
    <visual>
      <origin
        xyz="0 0 0"
        rpy="0 0 0" />
      <geometry>
        <mesh
          filename="package://manipulator/meshes/6Link.STL" />
      </geometry>
      <material
        name="">
        <color
          rgba="0.411764705882353 0.411764705882353 0.411764705882353 1" />
      </material>
    </visual>
    <collision>
      <origin
        xyz="0 0 0"
        rpy="0 0 0" />
      <geometry>
        <mesh
          filename="package://manipulator/meshes/6Link.STL" />
      </geometry>
    </collision>
  </link>
  <joint
    name="6-joint"
    type="continuous">
    <origin
      xyz="0.0943519303016779 0.0310000000000022 -0.0413143225570544"
      rpy="0 0 0" />
    <parent
      link="5_Link" />
    <child
      link="6Link" />
    <axis
      xyz="-0.917582028180844 0 0.397546502386234" />
  </joint>
</robot>